Workbook
Name FLEXVORPCalc: 'Manual VARG'!$C$6
Name IN_SEASON: Constants!$C$2
Name QBVORPCalc: 'Manual VARG'!$C$2
Name RAISES_ENABLED: Constants!$C$4
Name RBVORPCalc: 'Manual VARG'!$C$3
Name SEASON: Constants!$C$3
Name TEVORPCalc: 'Manual VARG'!$C$5
Name VARG: Constants!$C$1
Name WRTEVORPCalc: 'Manual VARG'!$C$8
Name WRVORPCalc: 'Manual VARG'!$C$4

Sheet 2018 Projections
A1: Year | B1: PLAYER | C1: TEAM | D1: POS | E1: PASSING COMP | F1: PASSING ATT | G1: PASSING YDS | H1: PASSING TD | I1: PASSING INT | J1: RUSH ATT | K1: RUSH YDS | L1: RUSH TD | M1: REC | N1: REC YDS | O1: REC TD | P1: PROJ TOTAL PTS | Q1: ReplacementValue | R1: VAR | S1: VAR/G | T1: Rookie | U1: LastProj | V1: VAR/G CHG | W1: Keeper? | X1: RFA? | Y1: VAWG | Z1: VAWG $ | AB1: Total Free Agent $ Pool | AC1: 2760
A2: 2018 | B2: Aaron Rodgers | C2: GB | D2: QB | E2: 361 | F2: 566 | G2: 4024 | H2: 34 | I2: 9 | J2: 58 | K2: 309 | L2: 2 | M2: 0 | N2: 0 | O2: 0 | P2: 321.86 | Q2: 278.68 | R2: 43.18 | S2: 2.69875 | U2: 321.86 | V2: =IF(ABS(Proj2018[[#This Row],[LastProj]]-Proj2018[[#This Row],[PROJ TOTAL PTS]])<0.5,"",(Proj2018[[#This Row],[PROJ TOTAL PTS]]-Proj2018[[#This Row],[LastProj]])/16) | W2: K | Y2: =IF(Proj2018[[#This Row],[POS]]="K",-100,Proj2018[[#This Row],[VAR/G]]+1.5) -> 4.19875 | Z2: =ROUND(MAX(Proj2018[[#This Row],[VAWG]],0)*$AC$9,0)+1 -> 483 | AB2: Free Agent $/VARG | AC2: 12.194044
A3: 2018 | B3: Tom Brady | C3: NE | D3: QB | E3: 391 | F3: 606 | G3: 4729 | H3: 33 | I3: 8 | J3: 30 | K3: 30 | L3: 2 | M3: 0 | N3: 0 | O3: 0 | P3: 320.16 | Q3: 278.68 | R3: 41.48 | S3: 2.5925 | U3: 320.16 | V3: =IF(ABS(Proj2018[[#This Row],[LastProj]]-Proj2018[[#This Row],[PROJ TOTAL PTS]])<0.5,"",(Proj2018[[#This Row],[PROJ TOTAL PTS]]-Proj2018[[#This Row],[LastProj]])/16) | W3: K | Y3: =IF(Proj2018[[#This Row],[POS]]="K",-100,Proj2018[[#This Row],[VAR/G]]+1.5) -> 4.0925 | Z3: =ROUND(MAX(Proj2018[[#This Row],[VAWG]],0)*$AC$9,0)+1 -> 471
A4: 2018 | B4: Cam Newton | C4: Car | D4: QB | E4: 313 | F4: 530 | G4: 3761 | H4: 22 | I4: 14 | J4: 128 | K4: 627 | L4: 6 | M4: 0 | N4: 0 | O4: 0 | P4: 309.14 | Q4: 278.68 | R4: 30.46 | S4: 1.90375 | U4: 309.14 | V4: =IF(ABS(Proj2018[[#This Row],[LastProj]]-Proj2018[[#This Row],[PROJ TOTAL PTS]])<0.5,"",(Proj2018[[#This Row],[PROJ TOTAL PTS]]-Proj2018[[#This Row],[LastProj]])/16) | W4: K | Y4: =IF(Proj2018[[#This Row],[POS]]="K",-100,Proj2018[[#This Row],[VAR/G]]+1.5) -> 3.40375 | Z4: =ROUND(MAX(Proj2018[[#This Row],[VAWG]],0)*$AC$9,0)+1 -> 392 | AB4: Optimal $/VARG | AC4: 12.194044
A5: 2018 | B5: Carson Wentz | C5: Phi | D5: QB | E5: 358 | F5: 578 | G5: 4148 | H5: 30 | I5: 12 | J5: 70 | K5: 272 | L5: 3 | M5: 0 | N5: 0 | O5: 0 | P5: 307.12 | Q5: 278.68 | R5: 28.44 | S5: 1.7775 | U5: 307.12 | V5: =IF(ABS(Proj2018[[#This Row],[LastProj]]-Proj2018[[#This Row],[PROJ TOTAL PTS]])<0.5,"",(Proj2018[[#This Row],[PROJ TOTAL PTS]]-Proj2018[[#This Row],[LastProj]])/16) | W5: K | Y5: =IF(Proj2018[[#This Row],[POS]]="K",-100,Proj2018[[#This Row],[VAR/G]]+1.5) -> 3.2775 | Z5: =ROUND(MAX(Proj2018[[#This Row],[VAWG]],0)*$AC$9,0)+1 -> 377
A6: 2018 | B6: Russell Wilson | C6: Sea | D6: QB | E6: 322 | F6: 521 | G6: 3826 | H6: 27 | I6: 11 | J6: 92 | K6: 484 | L6: 2 | M6: 0 | N6: 0 | O6: 0 | P6: 299.44 | Q6: 278.68 | R6: 20.76 | S6: 1.2975 | U6: 299.44 | V6: =IF(ABS(Proj2018[[#This Row],[LastProj]]-Proj2018[[#This Row],[PROJ TOTAL PTS]])<0.5,"",(Proj2018[[#This Row],[PROJ TOTAL PTS]]-Proj2018[[#This Row],[LastProj]])/16) | W6: K | Y6: =IF(Proj2018[[#This Row],[POS]]="K",-100,Proj2018[[#This Row],[VAR/G]]+1.5) -> 2.7975 | Z6: =ROUND(MAX(Proj2018[[#This Row],[VAWG]],0)*$AC$9,0)+1 -> 322 | AB6: Balance Point VARG | AC6: =AC1/AC4 -> 226.34
A7: 2018 | B7: Andrew Luck | C7: Ind | D7: QB | E7: 366 | F7: 585 | G7: 4294 | H7: 29 | I7: 16 | J7: 60 | K7: 285 | L7: 2 | M7: 0 | N7: 0 | O7: 0 | P7: 296.26 | Q7: 278.68 | R7: 17.58 | S7: 1.09875 | U7: 296.26 | V7: =IF(ABS(Proj2018[[#This Row],[LastProj]]-Proj2018[[#This Row],[PROJ TOTAL PTS]])<0.5,"",(Proj2018[[#This Row],[PROJ TOTAL PTS]]-Proj2018[[#This Row],[LastProj]])/16) | W7: K | Y7: =IF(Proj2018[[#This Row],[POS]]="K",-100,Proj2018[[#This Row],[VAR/G]]+1.5) -> 2.59875 | Z7: =ROUND(MAX(Proj2018[[#This Row],[VAWG]],0)*$AC$9,0)+1 -> 299 | AB7: Total VARG | AC7: =SUMIFS(Proj2018[VAWG],Proj2018[VAWG],">0",Proj2018[Keeper?],"") -> 24.04375
A8: 2018 | B8: Alex Smith | C8: Was | D8: QB | E8: 359 | F8: 557 | G8: 4142 | H8: 24 | I8: 8 | J8: 57 | K8: 300 | L8: 2 | M8: 0 | N8: 0 | O8: 0 | P8: 287.68 | Q8: 278.68 | R8: 9 | S8: 0.5625 | U8: 287.68 | V8: =IF(ABS(Proj2018[[#This Row],[LastProj]]-Proj2018[[#This Row],[PROJ TOTAL PTS]])<0.5,"",(Proj2018[[#This Row],[PROJ TOTAL PTS]]-Proj2018[[#This Row],[LastProj]])/16) | W8: K | Y8: =IF(Proj2018[[#This Row],[POS]]="K",-100,Proj2018[[#This Row],[VAR/G]]+1.5) -> 2.0625 | Z8: =ROUND(MAX(Proj2018[[#This Row],[VAWG]],0)*$AC$9,0)+1 -> 238
A9: 2018 | B9: Deshaun Watson | C9: Hou | D9: QB | E9: 309 | F9: 514 | G9: 3722 | H9: 27 | I9: 17 | J9: 87 | K9: 444 | L9: 3 | M9: 0 | N9: 0 | O9: 0 | P9: 285.28 | Q9: 278.68 | R9: 6.6 | S9: 0.4125 | U9: 285.28 | V9: =IF(ABS(Proj2018[[#This Row],[LastProj]]-Proj2018[[#This Row],[PROJ TOTAL PTS]])<0.5,"",(Proj2018[[#This Row],[PROJ TOTAL PTS]]-Proj2018[[#This Row],[LastProj]])/16) | W9: K | Y9: =IF(Proj2018[[#This Row],[POS]]="K",-100,Proj2018[[#This Row],[VAR/G]]+1.5) -> 1.9125 | Z9: =ROUND(MAX(Proj2018[[#This Row],[VAWG]],0)*$AC$9,0)+1 -> 221 | AB9: $/VAWG | AC9: =AC1/AC7 -> 114.79075
A10: 2018 | B10: Matthew Stafford | C10: Det | D10: QB | E10: 373 | F10: 575 | G10: 4392 | H10: 28 | I10: 11 | J10: 31 | K10: 104 | L10: 1 | M10: 0 | N10: 0 | O10: 0 | P10: 282.08 | Q10: 278.68 | R10: 3.4 | S10: 0.2125 | U10: 282.08 | V10: =IF(ABS(Proj2018[[#This Row],[LastProj]]-Proj2018[[#This Row],[PROJ TOTAL PTS]])<0.5,"",(Proj2018[[#This Row],[PROJ TOTAL PTS]]-Proj2018[[#This Row],[LastProj]])/16) | W10: K | Y10: =IF(Proj2018[[#This Row],[POS]]="K",-100,Proj2018[[#This Row],[VAR/G]]+1.5) -> 1.7125 | Z10: =ROUND(MAX(Proj2018[[#This Row],[VAWG]],0)*$AC$9,0)+1 -> 198
A11: 2018 | B11: Drew Brees | C11: NO | D11: QB | E11: 386 | F11: 569 | G11: 4405 | H11: 28 | I11: 12 | J11: 27 | K11: 31 | L11: 2 | M11: 0 | N11: 0 | O11: 0 | P11: 279.3 | Q11: 278.68 | R11: 0.62 | S11: 0.03875 | U11: 279.3 | V11: =IF(ABS(Proj2018[[#This Row],[LastProj]]-Proj2018[[#This Row],[PROJ TOTAL PTS]])<0.5,"",(Proj2018[[#This Row],[PROJ TOTAL PTS]]-Proj2018[[#This Row],[LastProj]])/16) | W11: K | Y11: =IF(Proj2018[[#This Row],[POS]]="K",-100,Proj2018[[#This Row],[VAR/G]]+1.5) -> 1.53875 | Z11: =ROUND(MAX(Proj2018[[#This Row],[VAWG]],0)*$AC$9,0)+1 -> 178
A12: 2018 | B12: Ben Roethlisberger | C12: Pit | D12: QB | E12: 376 | F12: 584 | G12: 4534 | H12: 29 | I12: 15 | J12: 28 | K12: 58 | L12: 1 | M12: 0 | N12: 0 | O12: 0 | P12: 279.16 | Q12: 278.68 | R12: 0.48 | S12: 0.03 | U12: 279.16 | V12: =IF(ABS(Proj2018[[#This Row],[LastProj]]-Proj2018[[#This Row],[PROJ TOTAL PTS]])<0.5,"",(Proj2018[[#This Row],[PROJ TOTAL PTS]]-Proj2018[[#This Row],[LastProj]])/16) | W12: K | Y12: =IF(Proj2018[[#This Row],[POS]]="K",-100,Proj2018[[#This Row],[VAR/G]]+1.5) -> 1.53 | Z12: =ROUND(MAX(Proj2018[[#This Row],[VAWG]],0)*$AC$9,0)+1 -> 177
A13: 2018 | B13: Kirk Cousins | C13: Min | D13: QB | E13: 373 | F13: 572 | G13: 4328 | H13: 27 | I13: 14 | J13: 47 | K13: 136 | L13: 2 | M13: 0 | N13: 0 | O13: 0 | P13: 278.72 | Q13: 278.68 | R13: 0.04 | S13: 0.0025 | U13: 278.72 | V13: =IF(ABS(Proj2018[[#This Row],[LastProj]]-Proj2018[[#This Row],[PROJ TOTAL PTS]])<0.5,"",(Proj2018[[#This Row],[PROJ TOTAL PTS]]-Proj2018[[#This Row],[LastProj]])/16) | W13: K | Y13: =IF(Proj2018[[#This Row],[POS]]="K",-100,Proj2018[[#This Row],[VAR/G]]+1.5) -> 1.5025 | Z13: =ROUND(MAX(Proj2018[[#This Row],[VAWG]],0)*$AC$9,0)+1 -> 173
A14: 2018 | B14: Marcus Mariota | C14: Ten | D14: QB | E14: 326 | F14: 529 | G14: 3777 | H14: 24 | I14: 13 | J14: 67 | K14: 366 | L14: 3 | M14: 0 | N14: 0 | O14: 0 | P14: 275.68 | Q14: 278.68 | R14: -3 | S14: -0.1875 | U14: 275.68 | V14: =IF(ABS(Proj2018[[#This Row],[LastProj]]-Proj2018[[#This Row],[PROJ TOTAL PTS]])<0.5,"",(Proj2018[[#This Row],[PROJ TOTAL PTS]]-Proj2018[[#This Row],[LastProj]])/16) | W14: K | Y14: =IF(Proj2018[[#This Row],[POS]]="K",-100,Proj2018[[#This Row],[VAR/G]]+1.5) -> 1.3125 | Z14: =ROUND(MAX(Proj2018[[#This Row],[VAWG]],0)*$AC$9,0)+1 -> 152
A15: 2018 | B15: Patrick Mahomes | C15: KC | D15: QB | E15: 344 | F15: 548 | G15: 4118 | H15: 22 | I15: 15 | J15: 66 | K15: 344 | L15: 3 | M15: 0 | N15: 0 | O15: 0 | P15: 275.12 | Q15: 278.68 | R15: -3.56 | S15: -0.2225 | U15: 275.12 | V15: =IF(ABS(Proj2018[[#This Row],[LastProj]]-Proj2018[[#This Row],[PROJ TOTAL PTS]])<0.5,"",(Proj2018[[#This Row],[PROJ TOTAL PTS]]-Proj2018[[#This Row],[LastProj]])/16) | W15: K | Y15: =IF(Proj2018[[#This Row],[POS]]="K",-100,Proj2018[[#This Row],[VAR/G]]+1.5) -> 1.2775 | Z15: =ROUND(MAX(Proj2018[[#This Row],[VAWG]],0)*$AC$9,0)+1 -> 148
A16: 2018 | B16: Le'Veon Bell | C16: Pit | D16: RB | E16: 0 | F16: 0 | G16: 0 | H16: 0 | I16: 0 | J16: 307 | K16: 1319 | L16: 10 | M16: 79 | N16: 635 | O16: 3 | P16: 273.4 | Q16: 118.8 | R16: 154.6 | S16: 9.6625 | U16: 273.4 | V16: =IF(ABS(Proj2018[[#This Row],[LastProj]]-Proj2018[[#This Row],[PROJ TOTAL PTS]])<0.5,"",(Proj2018[[#This Row],[PROJ TOTAL PTS]]-Proj2018[[#This Row],[LastProj]])/16) | W16: K | Y16: =IF(Proj2018[[#This Row],[POS]]="K",-100,Proj2018[[#This Row],[VAR/G]]+1.5) -> 11.1625 | Z16: =ROUND(MAX(Proj2018[[#This Row],[VAWG]],0)*$AC$9,0)+1 -> 1282
A17: 2018 | B17: Matt Ryan | C17: Atl | D17: QB | E17: 357 | F17: 550 | G17: 4307 | H17: 26 | I17: 10 | J17: 33 | K17: 108 | L17: 1 | M17: 0 | N17: 0 | O17: 0 | P17: 273.08 | Q17: 278.68 | R17: -5.6 | S17: -0.35 | U17: 273.08 | V17: =IF(ABS(Proj2018[[#This Row],[LastProj]]-Proj2018[[#This Row],[PROJ TOTAL PTS]])<0.5,"",(Proj2018[[#This Row],[PROJ TOTAL PTS]]-Proj2018[[#This Row],[LastProj]])/16) | W17: K | Y17: =IF(Proj2018[[#This Row],[POS]]="K",-100,Proj2018[[#This Row],[VAR/G]]+1.5) -> 1.15 | Z17: =ROUND(MAX(Proj2018[[#This Row],[VAWG]],0)*$AC$9,0)+1 -> 133
A18: 2018 | B18: Jimmy Garoppolo | C18: SF | D18: QB | E18: 377 | F18: 591 | G18: 4354 | H18: 24 | I18: 13 | J18: 43 | K18: 107 | L18: 2 | M18: 0 | N18: 0 | O18: 0 | P18: 266.86 | Q18: 278.68 | R18: -11.82 | S18: -0.73875 | U18: 266.86 | V18: =IF(ABS(Proj2018[[#This Row],[LastProj]]-Proj2018[[#This Row],[PROJ TOTAL PTS]])<0.5,"",(Proj2018[[#This Row],[PROJ TOTAL PTS]]-Proj2018[[#This Row],[LastProj]])/16) | W18: K | Y18: =IF(Proj2018[[#This Row],[POS]]="K",-100,Proj2018[[#This Row],[VAR/G]]+1.5) -> 0.76125 | Z18: =ROUND(MAX(Proj2018[[#This Row],[VAWG]],0)*$AC$9,0)+1 -> 88
A19: 2018 | B19: Philip Rivers | C19: LAC | D19: QB | E19: 362 | F19: 576 | G19: 4336 | H19: 28 | I19: 12 | J19: 24 | K19: 49 | L19: 0 | M19: 0 | N19: 0 | O19: 0 | P19: 266.34 | Q19: 278.68 | R19: -12.34 | S19: -0.77125 | U19: 266.34 | V19: =IF(ABS(Proj2018[[#This Row],[LastProj]]-Proj2018[[#This Row],[PROJ TOTAL PTS]])<0.5,"",(Proj2018[[#This Row],[PROJ TOTAL PTS]]-Proj2018[[#This Row],[LastProj]])/16) | W19: K | Y19: =IF(Proj2018[[#This Row],[POS]]="K",-100,Proj2018[[#This Row],[VAR/G]]+1.5) -> 0.72875 | Z19: =ROUND(MAX(Proj2018[[#This Row],[VAWG]],0)*$AC$9,0)+1 -> 85
A20: 2018 | B20: Todd Gurley II | C20: LAR | D20: RB | E20: 0 | F20: 0 | G20: 0 | H20: 0 | I20: 0 | J20: 284 | K20: 1274 | L20: 10 | M20: 67 | N20: 595 | O20: 3 | P20: 264.9 | Q20: 118.8 | R20: 146.1 | S20: 9.13125 | U20: 264.9 | V20: =IF(ABS(Proj2018[[#This Row],[LastProj]]-Proj2018[[#This Row],[PROJ TOTAL PTS]])<0.5,"",(Proj2018[[#This Row],[PROJ TOTAL PTS]]-Proj2018[[#This Row],[LastProj]])/16) | W20: K | Y20: =IF(Proj2018[[#This Row],[POS]]="K",-100,Proj2018[[#This Row],[VAR/G]]+1.5) -> 10.63125 | Z20: =ROUND(MAX(Proj2018[[#This Row],[VAWG]],0)*$AC$9,0)+1 -> 1221
A21: 2018 | B21: Mitchell Trubisky | C21: Chi | D21: QB | E21: 347 | F21: 567 | G21: 3949 | H21: 23 | I21: 13 | J21: 63 | K21: 280 | L21: 2 | M21: 0 | N21: 0 | O21: 0 | P21: 263.96 | Q21: 278.68 | R21: -14.72 | S21: -0.92 | U21: 263.96 | V21: =IF(ABS(Proj2018[[#This Row],[LastProj]]-Proj2018[[#This Row],[PROJ TOTAL PTS]])<0.5,"",(Proj2018[[#This Row],[PROJ TOTAL PTS]]-Proj2018[[#This Row],[LastProj]])/16) | W21: K | Y21: =IF(Proj2018[[#This Row],[POS]]="K",-100,Proj2018[[#This Row],[VAR/G]]+1.5) -> 0.58 | Z21: =ROUND(MAX(Proj2018[[#This Row],[VAWG]],0)*$AC$9,0)+1 -> 68
... A23: 2018 | B23: Andy Dalton | C23: Cin | D23: QB | E23: 344 | F23: 558 | G23: 4009 | H23: 24 | I23: 11 | J23: 44 | K23: 154 | L23: 1 | M23: 0 | N23: 0 | O23: 0 | P23: 255.76 | Q23: 278.68 | R23: -22.92 | S23: -1.4325 | U23: 255.76 | V23: =IF(ABS(Proj2018[[#This Row],[LastProj]]-Proj2018[[#This Row],[PROJ TOTAL PTS]])<0.5,"",(Proj2018[[#This Row],[PROJ TOTAL PTS]]-Proj2018[[#This Row],[LastProj]])/16) | W23: K | Y23: =IF(Proj2018[[#This Row],[POS]]="K",-100,Proj2018[[#This Row],[VAR/G]]+1.5) -> 0.0675 | Z23: =ROUND(MAX(Proj2018[[#This Row],[VAWG]],0)*$AC$9,0)+1 -> 9
A24: 2018 | B24: Ryan Tannehill | C24: Mia | D24: QB | E24: 364 | F24: 571 | G24: 4150 | H24: 23 | I24: 14 | J24: 41 | K24: 186 | L24: 1 | M24: 0 | N24: 0 | O24: 0 | P24: 254.6 | Q24: 278.68 | R24: -24.08 | S24: -1.505 | U24: 254.6 | V24: =IF(ABS(Proj2018[[#This Row],[LastProj]]-Proj2018[[#This Row],[PROJ TOTAL PTS]])<0.5,"",(Proj2018[[#This Row],[PROJ TOTAL PTS]]-Proj2018[[#This Row],[LastProj]])/16) | Y24: =IF(Proj2018[[#This Row],[POS]]="K",-100,Proj2018[[#This Row],[VAR/G]]+1.5) -> -0.005 | Z24: =ROUND(MAX(Proj2018[[#This Row],[VAWG]],0)*$AC$9,0)+1 -> 1
A25: 2018 | B25: Dak Prescott | C25: Dal | D25: QB | E25: 325 | F25: 515 | G25: 3697 | H25: 21 | I25: 13 | J25: 56 | K25: 306 | L25: 3 | M25: 0 | N25: 0 | O25: 0 | P25: 254.48 | Q25: 278.68 | R25: -24.2 | S25: -1.5125 | U25: 254.48 | V25: =IF(ABS(Proj2018[[#This Row],[LastProj]]-Proj2018[[#This Row],[PROJ TOTAL PTS]])<0.5,"",(Proj2018[[#This Row],[PROJ TOTAL PTS]]-Proj2018[[#This Row],[LastProj]])/16) | W25: K | Y25: =IF(Proj2018[[#This Row],[POS]]="K",-100,Proj2018[[#This Row],[VAR/G]]+1.5) -> -0.0125 | Z25: =ROUND(MAX(Proj2018[[#This Row],[VAWG]],0)*$AC$9,0)+1 -> 1
A26: 2018 | B26: Blake Bortles | C26: Jax | D26: QB | E26: 324 | F26: 533 | G26: 3725 | H26: 20 | I26: 12 | J26: 58 | K26: 333 | L26: 2 | M26: 0 | N26: 0 | O26: 0 | P26: 250.3 | Q26: 278.68 | R26: -28.38 | S26: -1.77375 | U26: 250.3 | V26: =IF(ABS(Proj2018[[#This Row],[LastProj]]-Proj2018[[#This Row],[PROJ TOTAL PTS]])<0.5,"",(Proj2018[[#This Row],[PROJ TOTAL PTS]]-Proj2018[[#This Row],[LastProj]])/16) | Y26: =IF(Proj2018[[#This Row],[POS]]="K",-100,Proj2018[[#This Row],[VAR/G]]+1.5) -> -0.27375 | Z26: =ROUND(MAX(Proj2018[[#This Row],[VAWG]],0)*$AC$9,0)+1 -> 1
A27: 2018 | B27: Ezekiel Elliott | C27: Dal | D27: RB | E27: 0 | F27: 0 | G27: 0 | H27: 0 | I27: 0 | J27: 324 | K27: 1404 | L27: 11 | M27: 44 | N27: 370 | O27: 1 | P27: 249.4 | Q27: 118.8 | R27: 130.6 | S27: 8.1625 | U27: 249.4 | V27: =IF(ABS(Proj2018[[#This Row],[LastProj]]-Proj2018[[#This Row],[PROJ TOTAL PTS]])<0.5,"",(Proj2018[[#This Row],[PROJ TOTAL PTS]]-Proj2018[[#This Row],[LastProj]])/16) | W27: K | Y27: =IF(Proj2018[[#This Row],[POS]]="K",-100,Proj2018[[#This Row],[VAR/G]]+1.5) -> 9.6625 | Z27: =ROUND(MAX(Proj2018[[#This Row],[VAWG]],0)*$AC$9,0)+1 -> 1110
A28: 2018 | B28: David Johnson | C28: Ari | D28: RB | E28: 0 | F28: 0 | G28: 0 | H28: 0 | I28: 0 | J28: 266 | K28: 1087 | L28: 8 | M28: 77 | N28: 739 | O28: 3 | P28: 248.6 | Q28: 118.8 | R28: 129.8 | S28: 8.1125 | U28: 248.6 | V28: =IF(ABS(Proj2018[[#This Row],[LastProj]]-Proj2018[[#This Row],[PROJ TOTAL PTS]])<0.5,"",(Proj2018[[#This Row],[PROJ TOTAL PTS]]-Proj2018[[#This Row],[LastProj]])/16) | W28: K | Y28: =IF(Proj2018[[#This Row],[POS]]="K",-100,Proj2018[[#This Row],[VAR/G]]+1.5) -> 9.6125 | Z28: =ROUND(MAX(Proj2018[[#This Row],[VAWG]],0)*$AC$9,0)+1 -> 1104
A29: 2018 | B29: Case Keenum | C29: Den | D29: QB | E29: 368 | F29: 588 | G29: 4092 | H29: 22 | I29: 12 | J29: 40 | K29: 144 | L29: 1 | M29: 0 | N29: 0 | O29: 0 | P29: 248.08 | Q29: 278.68 | R29: -30.6 | S29: -1.9125 | U29: 248.08 | V29: =IF(ABS(Proj2018[[#This Row],[LastProj]]-Proj2018[[#This Row],[PROJ TOTAL PTS]])<0.5,"",(Proj2018[[#This Row],[PROJ TOTAL PTS]]-Proj2018[[#This Row],[LastProj]])/16) | Y29: =IF(Proj2018[[#This Row],[POS]]="K",-100,Proj2018[[#This Row],[VAR/G]]+1.5) -> -0.4125 | Z29: =ROUND(MAX(Proj2018[[#This Row],[VAWG]],0)*$AC$9,0)+1 -> 1
A30: 2018 | B30: Derek Carr | C30: Oak | D30: QB | E30: 352 | F30: 574 | G30: 3963 | H30: 24 | I30: 12 | J30: 32 | K30: 89 | L30: 1 | M30: 0 | N30: 0 | O30: 0 | P30: 245.42 | Q30: 278.68 | R30: -33.26 | S30: -2.07875 | U30: 245.42 | V30: =IF(ABS(Proj2018[[#This Row],[LastProj]]-Proj2018[[#This Row],[PROJ TOTAL PTS]])<0.5,"",(Proj2018[[#This Row],[PROJ TOTAL PTS]]-Proj2018[[#This Row],[LastProj]])/16) | W30: K | Y30: =IF(Proj2018[[#This Row],[POS]]="K",-100,Proj2018[[#This Row],[VAR/G]]+1.5) -> -0.57875 | Z30: =ROUND(MAX(Proj2018[[#This Row],[VAWG]],0)*$AC$9,0)+1 -> 1
A31: 2018 | B31: Eli Manning | C31: NYG | D31: QB | E31: 369 | F31: 598 | G31: 4107 | H31: 26 | I31: 15 | J31: 18 | K31: 27 | L31: 0 | M31: 0 | N31: 0 | O31: 0 | P31: 240.98 | Q31: 278.68 | R31: -37.7 | S31: -2.35625 | U31: 240.98 | V31: =IF(ABS(Proj2018[[#This Row],[LastProj]]-Proj2018[[#This Row],[PROJ TOTAL PTS]])<0.5,"",(Proj2018[[#This Row],[PROJ TOTAL PTS]]-Proj2018[[#This Row],[LastProj]])/16) | Y31: =IF(Proj2018[[#This Row],[POS]]="K",-100,Proj2018[[#This Row],[VAR/G]]+1.5) -> -0.85625 | Z31: =ROUND(MAX(Proj2018[[#This Row],[VAWG]],0)*$AC$9,0)+1 -> 1
A32: 2018 | B32: Jameis Winston | C32: TB | D32: QB | E32: 290 | F32: 468 | G32: 3595 | H32: 23 | I32: 12 | J32: 38 | K32: 161 | L32: 1 | M32: 0 | N32: 0 | O32: 0 | P32: 233.9 | Q32: 278.68 | R32: -44.78 | S32: -2.79875 | U32: 233.9 | V32: =IF(ABS(Proj2018[[#This Row],[LastProj]]-Proj2018[[#This Row],[PROJ TOTAL PTS]])<0.5,"",(Proj2018[[#This Row],[PROJ TOTAL PTS]]-Proj2018[[#This Row],[LastProj]])/16) | Y32: =IF(Proj2018[[#This Row],[POS]]="K",-100,Proj2018[[#This Row],[VAR/G]]+1.5) -> -1.29875 | Z32: =ROUND(MAX(Proj2018[[#This Row],[VAWG]],0)*$AC$9,0)+1 -> 1
A33: 2018 | B33: Tyrod Taylor | C33: Cle | D33: QB | E33: 244 | F33: 395 | G33: 2764 | H33: 18 | I33: 6 | J33: 67 | K33: 384 | L33: 3 | M33: 0 | N33: 0 | O33: 0 | P33: 226.96 | Q33: 278.68 | R33: -51.72 | S33: -3.2325 | U33: 226.96 | V33: =IF(ABS(Proj2018[[#This Row],[LastProj]]-Proj2018[[#This Row],[PROJ TOTAL PTS]])<0.5,"",(Proj2018[[#This Row],[PROJ TOTAL PTS]]-Proj2018[[#This Row],[LastProj]])/16) | Y33: =IF(Proj2018[[#This Row],[POS]]="K",-100,Proj2018[[#This Row],[VAR/G]]+1.5) -> -1.7325 | Z33: =ROUND(MAX(Proj2018[[#This Row],[VAWG]],0)*$AC$9,0)+1 -> 1
A34: 2018 | B34: Saquon Barkley | C34: NYG | D34: RB | E34: 0 | F34: 0 | G34: 0 | H34: 0 | I34: 0 | J34: 258 | K34: 1133 | L34: 7 | M34: 60 | N34: 533 | O34: 3 | P34: 226.6 | Q34: 118.8 | R34: 107.8 | S34: 6.7375 | T34: Rookie | U34: 226.6 | V34: =IF(ABS(Proj2018[[#This Row],[LastProj]]-Proj2018[[#This Row],[PROJ TOTAL PTS]])<0.5,"",(Proj2018[[#This Row],[PROJ TOTAL PTS]]-Proj2018[[#This Row],[LastProj]])/16) | W34: K | Y34: =IF(Proj2018[[#This Row],[POS]]="K",-100,Proj2018[[#This Row],[VAR/G]]+1.5) -> 8.2375 | Z34: =ROUND(MAX(Proj2018[[#This Row],[VAWG]],0)*$AC$9,0)+1 -> 947
A35: 2018 | B35: Alvin Kamara | C35: NO | D35: RB | E35: 0 | F35: 0 | G35: 0 | H35: 0 | I35: 0 | J35: 186 | K35: 843 | L35: 8 | M35: 74 | N35: 716 | O35: 3 | P35: 221.9 | Q35: 118.8 | R35: 103.1 | S35: 6.44375 | U35: 221.9 | V35: =IF(ABS(Proj2018[[#This Row],[LastProj]]-Proj2018[[#This Row],[PROJ TOTAL PTS]])<0.5,"",(Proj2018[[#This Row],[PROJ TOTAL PTS]]-Proj2018[[#This Row],[LastProj]])/16) | W35: K | Y35: =IF(Proj2018[[#This Row],[POS]]="K",-100,Proj2018[[#This Row],[VAR/G]]+1.5) -> 7.94375 | Z35: =ROUND(MAX(Proj2018[[#This Row],[VAWG]],0)*$AC$9,0)+1 -> 913
A36: 2018 | B36: Leonard Fournette | C36: Jax | D36: RB | E36: 0 | F36: 0 | G36: 0 | H36: 0 | I36: 0 | J36: 310 | K36: 1202 | L36: 10 | M36: 40 | N36: 329 | O36: 1 | P36: 219.1 | Q36: 118.8 | R36: 100.3 | S36: 6.26875 | U36: 219.1 | V36: =IF(ABS(Proj2018[[#This Row],[LastProj]]-Proj2018[[#This Row],[PROJ TOTAL PTS]])<0.5,"",(Proj2018[[#This Row],[PROJ TOTAL PTS]]-Proj2018[[#This Row],[LastProj]])/16) | W36: K | Y36: =IF(Proj2018[[#This Row],[POS]]="K",-100,Proj2018[[#This Row],[VAR/G]]+1.5) -> 7.76875 | Z36: =ROUND(MAX(Proj2018[[#This Row],[VAWG]],0)*$AC$9,0)+1 -> 893
A37: 2018 | B37: Dalvin Cook | C37: Min | D37: RB | E37: 0 | F37: 0 | G37: 0 | H37: 0 | I37: 0 | J37: 261 | K37: 1108 | L37: 7 | M37: 54 | N37: 500 | O37: 2 | P37: 214.8 | Q37: 118.8 | R37: 96 | S37: 6 | U37: 214.8 | V37: =IF(ABS(Proj2018[[#This Row],[LastProj]]-Proj2018[[#This Row],[PROJ TOTAL PTS]])<0.5,"",(Proj2018[[#This Row],[PROJ TOTAL PTS]]-Proj2018[[#This Row],[LastProj]])/16) | W37: K | Y37: =IF(Proj2018[[#This Row],[POS]]="K",-100,Proj2018[[#This Row],[VAR/G]]+1.5) -> 7.5 | Z37: =ROUND(MAX(Proj2018[[#This Row],[VAWG]],0)*$AC$9,0)+1 -> 862
A38: 2018 | B38: Antonio Brown | C38: Pit | D38: WR | E38: 0 | F38: 0 | G38: 0 | H38: 0 | I38: 0 | J38: 0 | K38: 0 | L38: 0 | M38: 110 | N38: 1576 | O38: 9 | P38: 211.6 | Q38: 117.7 | R38: 93.9 | S38: 5.86875 | U38: 211.6 | V38: =IF(ABS(Proj2018[[#This Row],[LastProj]]-Proj2018[[#This Row],[PROJ TOTAL PTS]])<0.5,"",(Proj2018[[#This Row],[PROJ TOTAL PTS]]-Proj2018[[#This Row],[LastProj]])/16) | W38: K | Y38: =IF(Proj2018[[#This Row],[POS]]="K",-100,Proj2018[[#This Row],[VAR/G]]+1.5) -> 7.36875 | Z38: =ROUND(MAX(Proj2018[[#This Row],[VAWG]],0)*$AC$9,0)+1 -> 847
A39: 2018 | B39: Kareem Hunt | C39: KC | D39: RB | E39: 0 | F39: 0 | G39: 0 | H39: 0 | I39: 0 | J39: 236 | K39: 999 | L39: 8 | M39: 56 | N39: 450 | O39: 2 | P39: 204.9 | Q39: 118.8 | R39: 86.1 | S39: 5.38125 | U39: 204.9 | V39: =IF(ABS(Proj2018[[#This Row],[LastProj]]-Proj2018[[#This Row],[PROJ TOTAL PTS]])<0.5,"",(Proj2018[[#This Row],[PROJ TOTAL PTS]]-Proj2018[[#This Row],[LastProj]])/16) | W39: K | Y39: =IF(Proj2018[[#This Row],[POS]]="K",-100,Proj2018[[#This Row],[VAR/G]]+1.5) -> 6.88125 | Z39: =ROUND(MAX(Proj2018[[#This Row],[VAWG]],0)*$AC$9,0)+1 -> 791
A40: 2018 | B40: Joe Flacco | C40: Bal | D40: QB | E40: 343 | F40: 546 | G40: 3528 | H40: 18 | I40: 11 | J40: 25 | K40: 46 | L40: 1 | M40: 0 | N40: 0 | O40: 0 | P40: 201.72 | Q40: 278.68 | R40: -76.96 | S40: -4.81 | U40: 201.72 | V40: =IF(ABS(Proj2018[[#This Row],[LastProj]]-Proj2018[[#This Row],[PROJ TOTAL PTS]])<0.5,"",(Proj2018[[#This Row],[PROJ TOTAL PTS]]-Proj2018[[#This Row],[LastProj]])/16) | Y40: =IF(Proj2018[[#This Row],[POS]]="K",-100,Proj2018[[#This Row],[VAR/G]]+1.5) -> -3.31 | Z40: =ROUND(MAX(Proj2018[[#This Row],[VAWG]],0)*$AC$9,0)+1 -> 1
A41: 2018 | B41: LeSean McCoy | C41: Buf | D41: RB | E41: 0 | F41: 0 | G41: 0 | H41: 0 | I41: 0 | J41: 244 | K41: 1098 | L41: 6 | M41: 57 | N41: 437 | O41: 2 | P41: 201.5 | Q41: 118.8 | R41: 82.7 | S41: 5.16875 | U41: 201.5 | V41: =IF(ABS(Proj2018[[#This Row],[LastProj]]-Proj2018[[#This Row],[PROJ TOTAL PTS]])<0.5,"",(Proj2018[[#This Row],[PROJ TOTAL PTS]]-Proj2018[[#This Row],[LastProj]])/16) | W41: K | X41: RFA | Y41: =IF(Proj2018[[#This Row],[POS]]="K",-100,Proj2018[[#This Row],[VAR/G]]+1.5) -> 6.66875 | Z41: =ROUND(MAX(Proj2018[[#This Row],[VAWG]],0)*$AC$9,0)+1 -> 767
...

Sheet ESPNTeams
A1: Team ID | B1: Team | C1: Owner
A2: 4 | B2: R E L A X | C2: Sean Christopherson
A3: 5 | B3: House of Romanov | C3: David Tabachnick
A4: 6 | B4: Scrote Squad | C4: Jonny Max
A5: 7 | B5: Baldrick's Cunning Plan | C5: Gregory Germano
A6: 10 | B6: Strange Brew | C6: Josh Hellstrom
A7: 1 | B7: The Meme Team | C7: Adam Pranger
A8: 9 | B8: GawdDamn Trash Pandas | C8: Joe Nienalt
A9: 3 | B9: Nino and The Twerks | C9: David Opp
A10: 2 | B10: We Are All Doomed! | C10: Robert Noradki
A11: 8 | B11: Read Option Illiteracy | C11: SKYE BURLINGAME

Sheet Owners
A1: user_id | B1: team_name | C1: league_id | D1: display_name
A2: 78938523440660480 | B2: Baldrick's Cunning Plan | C2: 1313750925990465536 | D2: gregdg82
A3: 297161941346963456 | B3: The Replacements | C3: 1313750925990465536 | D3: GentlemanBrewer
A4: 342475185162694656 | B4: BILL BILL BILL BILL BILL | C4: 1313750925990465536 | D4: hellj85
A5: 342745172225974272 | C5: 1313750925990465536 | D5: demboys26
A6: 342747602523004928 | B6: Love Machines | C6: 1313750925990465536 | D6: BobbyBaby
A7: 342909084795711488 | B7: Los Pollos Hermanos | C7: 1313750925990465536 | D7: joe9alt
A8: 410283082055172096 | B8: Gettin Some Strange | C8: 1313750925990465536 | D8: Jonnymaxed
A9: 413095484094160896 | B9: Damar's Revenge | C9: 1313750925990465536 | D9: zombull
A10: 452206609343442944 | C10: 1313750925990465536 | D10: docopp
A11: 454379832487178240 | B11: Tin Plate Dengerate | C11: 1313750925990465536 | D11: cthultu
A12: 563130086871535616 | C12: 1313750925990465536 | D12: mcmahanwich

Sheet Full Roster
A1: player_id | B1: OWNER | C1: PLAYER | D1: RosterIndex | E1: DraftIndex | F1: TEAM | G1: POS | H1: SOURCE | I1: $ PREV | J1: Contract | K1: Contract Year | L1: RFA Eligible? | M1: FFA Year | N1: $↑ VAR | O1: $ CURR | P1: VAR/G | Q1: GoodVARG | R1: ManualVARG | S1: KEEPER / RFA | T1: Net Keeper Count | U1: RFA $ | V1: Optimal $ | W1: Opt Value | X1: VAW/G | Y1: VAWG Market $ | Z1: VAWG Value | AA1: Pure Inflated $ | AB1: Inflated Value | AC1: Age | AE1: FA Draft $ | AF1: OWNER | AG1: Keeper $ | AH1: Keeper + RFA | AI1: Roster Size | AJ1: Keepers # | AK1: RFA # | AL1: Penalty | AM1: Min Salary | AN1: VARG (K) | AO1: VARG (RFA) | AP1: VARG (non K) | AQ1: $ to VARG | AR1: Total VARG | AS1: Value
A2: 11603 | B2: BobbyBaby | C2: AJ Barner | D2: =_xlfn.IFNA(MATCH(RosterPlan25[[#This Row],[player_id]],CompositeRoster[sleeper_id],0), MATCH(RosterPlan25[[#This Row],[PLAYER]],CompositeRoster[full_name],0)) -> 1 | E2: =MATCH(RosterPlan25[[#This Row],[player_id]],Draft2025[sleeper_id],0) -> #N/A | F2: =INDEX(CompositeRoster[team],RosterPlan25[[#This Row],[RosterIndex]])&"" -> SEA | G2: =INDEX(CompositeRoster[position],RosterPlan25[[#This Row],[RosterIndex]])&"" -> TE | H2: =INDEX(CompositeRoster[source],RosterPlan25[[#This Row],[RosterIndex]]) -> Roster | I2: =_xlfn.IFNA(INDEX(Draft2025[PRICE],RosterPlan25[[#This Row],[DraftIndex]]),0) -> 0 | J2: =IF(RosterPlan25[[#This Row],[SOURCE]]="Rookie","Rookie",_xlfn.IFNA(INDEX(Draft2025[Current Contract],RosterPlan25[[#This Row],[DraftIndex]]),"Undrafted")) -> Undrafted | K2: {=IF(OR(ISBLANK(RosterPlan25[[#This Row],[player_id]]),NOT(ISNA(MATCH(RosterPlan25[[#This Row],[player_id]],INDIRECT("Rookies" & SEASON &"[player_id]"),0)))), SEASON, _xlfn.IFNA(INDEX(Draft2025[Contract Year],RosterPlan25[[#This Row],[DraftIndex]]),IF(IN_SEASON,SEASON,SEASON-1)))} -> 2025 | L2: =IF(_xlfn.IFNA(INDEX(Draft2025[KEEPER],RosterPlan25[[#This Row],[DraftIndex]]),"")="K","Yes","") | M2: {=IF(RosterPlan25[[#This Row],[Contract]]="Rookie", "", IF(_xlfn.IFNA(INDEX(Draft2025[Contract Year],RosterPlan25[[#This Row],[DraftIndex]]),IF(IN_SEASON,SEASON,SEASON-1))+3<SEASON, SEASON, _xlfn.IFNA(INDEX(Draft2025[Contract Year],RosterPlan25[[#This Row],[DraftIndex]]),IF(IN_SEASON,SEASON,SEASON-1))+3))} -> 2028 | N2: =ROUNDDOWN(RosterPlan25[[#This Row],[Optimal $]]*IF(RosterPlan25[[#This Row],[Contract]]="Rookie",0.3,0.15),0) -> 0 | O2: =IF(RosterPlan25[[#This Row],[SOURCE]]="Rookie", INDEX(INDIRECT("Rookies" & SEASON & "[salary]"),MATCH(RosterPlan25[[#This Row],[PLAYER]],INDIRECT("Rookies"& SEASON & "[full_name]"),0)), MAX(RosterPlan25[[#This Row],[$ PREV]] + IF(RAISES_ENABLED,RosterPlan25[[#This Row],[$↑ VAR]],0),1)) -> 1 | P2: =IF(VARG="MANUAL",RosterPlan25[[#This Row],[ManualVARG]],IF(VARG="GOOD",RosterPlan25[[#This Row],[GoodVARG]],"ERR")) -> -1.4633912 | Q2: =_xlfn.IFNA(IF(RosterPlan25[[#This Row],[POS]]="K",0,INDEX(GoodSheets[MG VARG],MATCH(TEXT(RosterPlan25[[#This Row],[player_id]],"0"),GoodSheets[sleeper_id],0))), IF(RosterPlan25[[#This Row],[POS]]="QB",-12,IF(RosterPlan25[[#This Row],[POS]]="RB",-8,IF(RosterPlan25[[#This Row],[POS]]="WR",-8,-5)))) -> -1.4633912 | R2: =_xlfn.IFNA(INDEX(ALL_Athletic[VARG], MATCH(RosterPlan25[[#This Row],[player_id]],ALL_Athletic[SleeperID],0)), IF(RosterPlan25[[#This Row],[POS]]="QB",-12,IF(RosterPlan25[[#This Row],[POS]]="RB",-8,IF(RosterPlan25[[#This Row],[POS]]="WR",-8,-5)))) -> -5 | S2: K | T2: =_xlfn.IFNA(INDEX(Draft2025[Net Keeper Count],RosterPlan25[[#This Row],[DraftIndex]]),0)+IF(RosterPlan25[[#This Row],[KEEPER / RFA]]="K",1,0) -> 1 | U2: =IF(RosterPlan25[[#This Row],[KEEPER / RFA]]="RFA",RosterPlan25[[#This Row],[Pure Inflated $]],"") | V2: =IF(RosterPlan25[[#This Row],[VAR/G]]>0, ROUND(IF(VARG="GOOD",$AG$29,IF(VARG="ATHLETIC",$AH$29,99999999999))*RosterPlan25[[#This Row],[VAR/G]],0), 0) + 1 -> 1 | W2: =RosterPlan25[[#This Row],[Optimal $]]-RosterPlan25[[#This Row],[$ CURR]] -> 0 | X2: =IF(OR(RosterPlan25[[#This Row],[SOURCE]]="Rookie",RosterPlan25[[#This Row],[POS]]="K"),0,RosterPlan25[[#This Row],[VAR/G]]+3.3) -> 1.8366088 | Y2: =IF(RosterPlan25[[#This Row],[VAW/G]]>0,ROUND(RosterPlan25[[#This Row],[VAW/G]]*$AG$56,0)+1,1) -> 31 | Z2: =RosterPlan25[[#This Row],[VAWG Market $]]-_xlfn.IFNA(RosterPlan25[[#This Row],[$ CURR]],1) -> 30 | AA2: =IF(RosterPlan25[[#This Row],[VAR/G]]>0,1+ROUND(RosterPlan25[[#This Row],[VAR/G]]*IF(RosterPlan25[[#This Row],[KEEPER / RFA]]="K",($AG$34+RosterPlan25[[#This Row],[$ CURR]]-1)/($AG$23+RosterPlan25[[#This Row],[VAR/G]]),$AG$35),0),1) -> 1 | AB2: =RosterPlan25[[#This Row],[Pure Inflated $]]-RosterPlan25[[#This Row],[$ CURR]] -> 0 | AC2: =INDEX(players[age],MATCH(RosterPlan25[[#This Row],[player_id]],players[sleeper_id],0)) -> 24 | AE2: =300-AG2+AI2+$AE$15-24-AL2 -> 215 | AF2: cthultu | AG2: =SUMIFS(RosterPlan25[[$ CURR]:[$ CURR]],RosterPlan25[[OWNER]:[OWNER]],"="&$AF2,RosterPlan25[[KEEPER / RFA]:[KEEPER / RFA]],"K") -> 89 | AH2: =SUMIFS(RosterPlan25[[$ CURR]:[$ CURR]],RosterPlan25[[OWNER]:[OWNER]],"="&$AF2,RosterPlan25[[KEEPER / RFA]:[KEEPER / RFA]],"K")+ SUMIFS(RosterPlan25[[RFA $]:[RFA $]],RosterPlan25[[OWNER]:[OWNER]],"="&$AF2,RosterPlan25[[KEEPER / RFA]:[KEEPER / RFA]],"RFA") -> 89 | AI2: =COUNTIFS(RosterPlan25[OWNER],"="&$AF2) -> 20 | AJ2: =COUNTIFS(RosterPlan25[OWNER],"="&$AF2,RosterPlan25[KEEPER / RFA],"K") -> 20 | AK2: =COUNTIFS(RosterPlan25[OWNER],"="&$AF2,RosterPlan25[KEEPER / RFA],"RFA") -> 0 | AM2: =AH2+24+AL2-MIN(AJ2+AK2,24) -> 93 | AN2: =SUMIFS(RosterPlan25[[VAR/G]:[VAR/G]],RosterPlan25[[OWNER]:[OWNER]],"="&$AF2,RosterPlan25[[KEEPER / RFA]:[KEEPER / RFA]],"K",RosterPlan25[[VAR/G]:[VAR/G]],">0") -> 4.799523 | AO2: =SUMIFS(RosterPlan25[[VAR/G]:[VAR/G]],RosterPlan25[[OWNER]:[OWNER]],"="&$AF2,RosterPlan25[[KEEPER / RFA]:[KEEPER / RFA]],"RFA",RosterPlan25[[VAR/G]:[VAR/G]],">0") -> 0 | AP2: =SUMIFS(RosterPlan25[[VAR/G]:[VAR/G]],RosterPlan25[[OWNER]:[OWNER]],"="&$AF2,RosterPlan25[[KEEPER / RFA]:[KEEPER / RFA]],"<>K",RosterPlan25[[VAR/G]:[VAR/G]],">0") -> 0 | AQ2: =(300-AM2)/IF(VARG="ATHLETIC",$AH$35,IF(VARG="GOOD",$AG$35,0)) -> 12.597641 | AR2: =AN2+AQ2+AO2 -> 17.397164 | AS2: 19.522489 | AT2: =AR2-AS2 -> -2.1253257 | AU2: =AR2/$AR$12 -> 0.074324076
A3: 11631 | B3: BobbyBaby | C3: Brian Thomas | D3: =_xlfn.IFNA(MATCH(RosterPlan25[[#This Row],[player_id]],CompositeRoster[sleeper_id],0), MATCH(RosterPlan25[[#This Row],[PLAYER]],CompositeRoster[full_name],0)) -> 2 | E3: =MATCH(RosterPlan25[[#This Row],[player_id]],Draft2025[sleeper_id],0) -> 7 | F3: =INDEX(CompositeRoster[team],RosterPlan25[[#This Row],[RosterIndex]])&"" -> JAX | G3: =INDEX(CompositeRoster[position],RosterPlan25[[#This Row],[RosterIndex]])&"" -> WR | H3: =INDEX(CompositeRoster[source],RosterPlan25[[#This Row],[RosterIndex]]) -> Roster | I3: =_xlfn.IFNA(INDEX(Draft2025[PRICE],RosterPlan25[[#This Row],[DraftIndex]]),0) -> 18 | J3: =IF(RosterPlan25[[#This Row],[SOURCE]]="Rookie","Rookie",_xlfn.IFNA(INDEX(Draft2025[Current Contract],RosterPlan25[[#This Row],[DraftIndex]]),"Undrafted")) -> Rookie | K3: {=IF(OR(ISBLANK(RosterPlan25[[#This Row],[player_id]]),NOT(ISNA(MATCH(RosterPlan25[[#This Row],[player_id]],INDIRECT("Rookies" & SEASON &"[player_id]"),0)))), SEASON, _xlfn.IFNA(INDEX(Draft2025[Contract Year],RosterPlan25[[#This Row],[DraftIndex]]),IF(IN_SEASON,SEASON,SEASON-1)))} -> 2024 | L3: =IF(_xlfn.IFNA(INDEX(Draft2025[KEEPER],RosterPlan25[[#This Row],[DraftIndex]]),"")="K","Yes","") -> Yes | M3: {=IF(RosterPlan25[[#This Row],[Contract]]="Rookie", "", IF(_xlfn.IFNA(INDEX(Draft2025[Contract Year],RosterPlan25[[#This Row],[DraftIndex]]),IF(IN_SEASON,SEASON,SEASON-1))+3<SEASON, SEASON, _xlfn.IFNA(INDEX(Draft2025[Contract Year],RosterPlan25[[#This Row],[DraftIndex]]),IF(IN_SEASON,SEASON,SEASON-1))+3))} | N3: =ROUNDDOWN(RosterPlan25[[#This Row],[Optimal $]]*IF(RosterPlan25[[#This Row],[Contract]]="Rookie",0.3,0.15),0) -> 2 | O3: =IF(RosterPlan25[[#This Row],[SOURCE]]="Rookie", INDEX(INDIRECT("Rookies" & SEASON & "[salary]"),MATCH(RosterPlan25[[#This Row],[PLAYER]],INDIRECT("Rookies"& SEASON & "[full_name]"),0)), MAX(RosterPlan25[[#This Row],[$ PREV]] + IF(RAISES_ENABLED,RosterPlan25[[#This Row],[$↑ VAR]],0),1)) -> 20 | P3: =IF(VARG="MANUAL",RosterPlan25[[#This Row],[ManualVARG]],IF(VARG="GOOD",RosterPlan25[[#This Row],[GoodVARG]],"ERR")) -> 0.47162003 | Q3: =_xlfn.IFNA(IF(RosterPlan25[[#This Row],[POS]]="K",0,INDEX(GoodSheets[MG VARG],MATCH(TEXT(RosterPlan25[[#This Row],[player_id]],"0"),GoodSheets[sleeper_id],0))), IF(RosterPlan25[[#This Row],[POS]]="QB",-12,IF(RosterPlan25[[#This Row],[POS]]="RB",-8,IF(RosterPlan25[[#This Row],[POS]]="WR",-8,-5)))) -> 0.47162003 | R3: =_xlfn.IFNA(INDEX(ALL_Athletic[VARG], MATCH(RosterPlan25[[#This Row],[player_id]],ALL_Athletic[SleeperID],0)), IF(RosterPlan25[[#This Row],[POS]]="QB",-12,IF(RosterPlan25[[#This Row],[POS]]="RB",-8,IF(RosterPlan25[[#This Row],[POS]]="WR",-8,-5)))) -> -8 | S3: K | T3: =_xlfn.IFNA(INDEX(Draft2025[Net Keeper Count],RosterPlan25[[#This Row],[DraftIndex]]),0)+IF(RosterPlan25[[#This Row],[KEEPER / RFA]]="K",1,0) -> 2 | U3: =IF(RosterPlan25[[#This Row],[KEEPER / RFA]]="RFA",RosterPlan25[[#This Row],[Pure Inflated $]],"") | V3: =IF(RosterPlan25[[#This Row],[VAR/G]]>0, ROUND(IF(VARG="GOOD",$AG$29,IF(VARG="ATHLETIC",$AH$29,99999999999))*RosterPlan25[[#This Row],[VAR/G]],0), 0) + 1 -> 7 | W3: =RosterPlan25[[#This Row],[Optimal $]]-RosterPlan25[[#This Row],[$ CURR]] -> -13 | X3: =IF(OR(RosterPlan25[[#This Row],[SOURCE]]="Rookie",RosterPlan25[[#This Row],[POS]]="K"),0,RosterPlan25[[#This Row],[VAR/G]]+3.3) -> 3.77162 | Y3: =IF(RosterPlan25[[#This Row],[VAW/G]]>0,ROUND(RosterPlan25[[#This Row],[VAW/G]]*$AG$56,0)+1,1) -> 63 | Z3: =RosterPlan25[[#This Row],[VAWG Market $]]-_xlfn.IFNA(RosterPlan25[[#This Row],[$ CURR]],1) -> 43 | AA3: =IF(RosterPlan25[[#This Row],[VAR/G]]>0,1+ROUND(RosterPlan25[[#This Row],[VAR/G]]*IF(RosterPlan25[[#This Row],[KEEPER / RFA]]="K",($AG$34+RosterPlan25[[#This Row],[$ CURR]]-1)/($AG$23+RosterPlan25[[#This Row],[VAR/G]]),$AG$35),0),1) -> 9 | AB3: =RosterPlan25[[#This Row],[Pure Inflated $]]-RosterPlan25[[#This Row],[$ CURR]] -> -11 | AC3: =INDEX(players[age],MATCH(RosterPlan25[[#This Row],[player_id]],players[sleeper_id],0)) -> 23 | AE3: =300-AG3+AI3+$AE$15-24-AL3 -> 133 | AF3: mcmahanwich | AG3: =SUMIFS(RosterPlan25[[$ CURR]:[$ CURR]],RosterPlan25[[OWNER]:[OWNER]],"="&$AF3,RosterPlan25[[KEEPER / RFA]:[KEEPER / RFA]],"K") -> 175 | AH3: =SUMIFS(RosterPlan25[[$ CURR]:[$ CURR]],RosterPlan25[[OWNER]:[OWNER]],"="&$AF3,RosterPlan25[[KEEPER / RFA]:[KEEPER / RFA]],"K")+ SUMIFS(RosterPlan25[[RFA $]:[RFA $]],RosterPlan25[[OWNER]:[OWNER]],"="&$AF3,RosterPlan25[[KEEPER / RFA]:[KEEPER / RFA]],"RFA") -> 175 | AI3: =COUNTIFS(RosterPlan25[OWNER],"="&$AF3) -> 24 | AJ3: =COUNTIFS(RosterPlan25[OWNER],"="&$AF3,RosterPlan25[KEEPER / RFA],"K") -> 24 | AK3: =COUNTIFS(RosterPlan25[OWNER],"="&$AF3,RosterPlan25[KEEPER / RFA],"RFA") -> 0 | AM3: =AH3+24+AL3-MIN(AJ3+AK3,24) -> 175 | AN3: =SUMIFS(RosterPlan25[[VAR/G]:[VAR/G]],RosterPlan25[[OWNER]:[OWNER]],"="&$AF3,RosterPlan25[[KEEPER / RFA]:[KEEPER / RFA]],"K",RosterPlan25[[VAR/G]:[VAR/G]],">0") -> 13.728754 | AO3: =SUMIFS(RosterPlan25[[VAR/G]:[VAR/G]],RosterPlan25[[OWNER]:[OWNER]],"="&$AF3,RosterPlan25[[KEEPER / RFA]:[KEEPER / RFA]],"RFA",RosterPlan25[[VAR/G]:[VAR/G]],">0") -> 0 | AP3: =SUMIFS(RosterPlan25[[VAR/G]:[VAR/G]],RosterPlan25[[OWNER]:[OWNER]],"="&$AF3,RosterPlan25[[KEEPER / RFA]:[KEEPER / RFA]],"<>K",RosterPlan25[[VAR/G]:[VAR/G]],">0") -> 0 | AQ3: =(300-AM3)/IF(VARG="ATHLETIC",$AH$35,IF(VARG="GOOD",$AG$35,0)) -> 7.6072709 | AR3: =AN3+AQ3+AO3 -> 21.336025 | AS3: 19.527714 | AT3: =AR3-AS3 -> 1.8083116 | AU3: =AR3/$AR$12 -> 0.091151661
A4: 10236 | B4: BobbyBaby | C4: Dalton Kincaid | D4: =_xlfn.IFNA(MATCH(RosterPlan25[[#This Row],[player_id]],CompositeRoster[sleeper_id],0), MATCH(RosterPlan25[[#This Row],[PLAYER]],CompositeRoster[full_name],0)) -> 3 | E4: =MATCH(RosterPlan25[[#This Row],[player_id]],Draft2025[sleeper_id],0) -> 8 | F4: =INDEX(CompositeRoster[team],RosterPlan25[[#This Row],[RosterIndex]])&"" -> BUF | G4: =INDEX(CompositeRoster[position],RosterPlan25[[#This Row],[RosterIndex]])&"" -> TE | H4: =INDEX(CompositeRoster[source],RosterPlan25[[#This Row],[RosterIndex]]) -> Roster | I4: =_xlfn.IFNA(INDEX(Draft2025[PRICE],RosterPlan25[[#This Row],[DraftIndex]]),0) -> 13 | J4: =IF(RosterPlan25[[#This Row],[SOURCE]]="Rookie","Rookie",_xlfn.IFNA(INDEX(Draft2025[Current Contract],RosterPlan25[[#This Row],[DraftIndex]]),"Undrafted")) -> Rookie | K4: {=IF(OR(ISBLANK(RosterPlan25[[#This Row],[player_id]]),NOT(ISNA(MATCH(RosterPlan25[[#This Row],[player_id]],INDIRECT("Rookies" & SEASON &"[player_id]"),0)))), SEASON, _xlfn.IFNA(INDEX(Draft2025[Contract Year],RosterPlan25[[#This Row],[DraftIndex]]),IF(IN_SEASON,SEASON,SEASON-1)))} -> 2023 | L4: =IF(_xlfn.IFNA(INDEX(Draft2025[KEEPER],RosterPlan25[[#This Row],[DraftIndex]]),"")="K","Yes","") -> Yes | M4: {=IF(RosterPlan25[[#This Row],[Contract]]="Rookie", "", IF(_xlfn.IFNA(INDEX(Draft2025[Contract Year],RosterPlan25[[#This Row],[DraftIndex]]),IF(IN_SEASON,SEASON,SEASON-1))+3<SEASON, SEASON, _xlfn.IFNA(INDEX(Draft2025[Contract Year],RosterPlan25[[#This Row],[DraftIndex]]),IF(IN_SEASON,SEASON,SEASON-1))+3))} | N4: =ROUNDDOWN(RosterPlan25[[#This Row],[Optimal $]]*IF(RosterPlan25[[#This Row],[Contract]]="Rookie",0.3,0.15),0) -> 2 | O4: =IF(RosterPlan25[[#This Row],[SOURCE]]="Rookie", INDEX(INDIRECT("Rookies" & SEASON & "[salary]"),MATCH(RosterPlan25[[#This Row],[PLAYER]],INDIRECT("Rookies"& SEASON & "[full_name]"),0)), MAX(RosterPlan25[[#This Row],[$ PREV]] + IF(RAISES_ENABLED,RosterPlan25[[#This Row],[$↑ VAR]],0),1)) -> 15 | P4: =IF(VARG="MANUAL",RosterPlan25[[#This Row],[ManualVARG]],IF(VARG="GOOD",RosterPlan25[[#This Row],[GoodVARG]],"ERR")) -> 0.63336655 | Q4: =_xlfn.IFNA(IF(RosterPlan25[[#This Row],[POS]]="K",0,INDEX(GoodSheets[MG VARG],MATCH(TEXT(RosterPlan25[[#This Row],[player_id]],"0"),GoodSheets[sleeper_id],0))), IF(RosterPlan25[[#This Row],[POS]]="QB",-12,IF(RosterPlan25[[#This Row],[POS]]="RB",-8,IF(RosterPlan25[[#This Row],[POS]]="WR",-8,-5)))) -> 0.63336655 | R4: =_xlfn.IFNA(INDEX(ALL_Athletic[VARG], MATCH(RosterPlan25[[#This Row],[player_id]],ALL_Athletic[SleeperID],0)), IF(RosterPlan25[[#This Row],[POS]]="QB",-12,IF(RosterPlan25[[#This Row],[POS]]="RB",-8,IF(RosterPlan25[[#This Row],[POS]]="WR",-8,-5)))) -> -0.46649975 | S4: K | T4: =_xlfn.IFNA(INDEX(Draft2025[Net Keeper Count],RosterPlan25[[#This Row],[DraftIndex]]),0)+IF(RosterPlan25[[#This Row],[KEEPER / RFA]]="K",1,0) -> 3 | U4: =IF(RosterPlan25[[#This Row],[KEEPER / RFA]]="RFA",RosterPlan25[[#This Row],[Pure Inflated $]],"") | V4: =IF(RosterPlan25[[#This Row],[VAR/G]]>0, ROUND(IF(VARG="GOOD",$AG$29,IF(VARG="ATHLETIC",$AH$29,99999999999))*RosterPlan25[[#This Row],[VAR/G]],0), 0) + 1 -> 8 | W4: =RosterPlan25[[#This Row],[Optimal $]]-RosterPlan25[[#This Row],[$ CURR]] -> -7 | X4: =IF(OR(RosterPlan25[[#This Row],[SOURCE]]="Rookie",RosterPlan25[[#This Row],[POS]]="K"),0,RosterPlan25[[#This Row],[VAR/G]]+3.3) -> 3.9333666 | Y4: =IF(RosterPlan25[[#This Row],[VAW/G]]>0,ROUND(RosterPlan25[[#This Row],[VAW/G]]*$AG$56,0)+1,1) -> 66 | Z4: =RosterPlan25[[#This Row],[VAWG Market $]]-_xlfn.IFNA(RosterPlan25[[#This Row],[$ CURR]],1) -> 51 | AA4: =IF(RosterPlan25[[#This Row],[VAR/G]]>0,1+ROUND(RosterPlan25[[#This Row],[VAR/G]]*IF(RosterPlan25[[#This Row],[KEEPER / RFA]]="K",($AG$34+RosterPlan25[[#This Row],[$ CURR]]-1)/($AG$23+RosterPlan25[[#This Row],[VAR/G]]),$AG$35),0),1) -> 11 | AB4: =RosterPlan25[[#This Row],[Pure Inflated $]]-RosterPlan25[[#This Row],[$ CURR]] -> -4 | AC4: =INDEX(players[age],MATCH(RosterPlan25[[#This Row],[player_id]],players[sleeper_id],0)) -> 26 | AE4: =300-AG4+AI4+$AE$15-24-AL4 -> 61 | AF4: GentlemanBrewer | AG4: =SUMIFS(RosterPlan25[[$ CURR]:[$ CURR]],RosterPlan25[[OWNER]:[OWNER]],"="&$AF4,RosterPlan25[[KEEPER / RFA]:[KEEPER / RFA]],"K") -> 241 | AH4: =SUMIFS(RosterPlan25[[$ CURR]:[$ CURR]],RosterPlan25[[OWNER]:[OWNER]],"="&$AF4,RosterPlan25[[KEEPER / RFA]:[KEEPER / RFA]],"K")+ SUMIFS(RosterPlan25[[RFA $]:[RFA $]],RosterPlan25[[OWNER]:[OWNER]],"="&$AF4,RosterPlan25[[KEEPER / RFA]:[KEEPER / RFA]],"RFA") -> 241 | AI4: =COUNTIFS(RosterPlan25[OWNER],"="&$AF4) -> 18 | AJ4: =COUNTIFS(RosterPlan25[OWNER],"="&$AF4,RosterPlan25[KEEPER / RFA],"K") -> 18 | AK4: =COUNTIFS(RosterPlan25[OWNER],"="&$AF4,RosterPlan25[KEEPER / RFA],"RFA") -> 0 | AM4: =AH4+24+AL4-MIN(AJ4+AK4,24) -> 247 | AN4: =SUMIFS(RosterPlan25[[VAR/G]:[VAR/G]],RosterPlan25[[OWNER]:[OWNER]],"="&$AF4,RosterPlan25[[KEEPER / RFA]:[KEEPER / RFA]],"K",RosterPlan25[[VAR/G]:[VAR/G]],">0") -> 20.105512 | AO4: =SUMIFS(RosterPlan25[[VAR/G]:[VAR/G]],RosterPlan25[[OWNER]:[OWNER]],"="&$AF4,RosterPlan25[[KEEPER / RFA]:[KEEPER / RFA]],"RFA",RosterPlan25[[VAR/G]:[VAR/G]],">0") -> 0 | AP4: =SUMIFS(RosterPlan25[[VAR/G]:[VAR/G]],RosterPlan25[[OWNER]:[OWNER]],"="&$AF4,RosterPlan25[[KEEPER / RFA]:[KEEPER / RFA]],"<>K",RosterPlan25[[VAR/G]:[VAR/G]],">0") -> 0 | AQ4: =(300-AM4)/IF(VARG="ATHLETIC",$AH$35,IF(VARG="GOOD",$AG$35,0)) -> 3.2254829 | AR4: =AN4+AQ4+AO4 -> 23.330995 | AS4: 24.008323 | AT4: =AR4-AS4 -> -0.67732798 | AU4: =AR4/$AR$12 -> 0.09967456
A5: 5870 | B5: BobbyBaby | C5: Daniel Jones | D5: =_xlfn.IFNA(MATCH(RosterPlan25[[#This Row],[player_id]],CompositeRoster[sleeper_id],0), MATCH(RosterPlan25[[#This Row],[PLAYER]],CompositeRoster[full_name],0)) -> 4 | E5: =MATCH(RosterPlan25[[#This Row],[player_id]],Draft2025[sleeper_id],0) -> 9 | F5: =INDEX(CompositeRoster[team],RosterPlan25[[#This Row],[RosterIndex]])&"" -> IND | G5: =INDEX(CompositeRoster[position],RosterPlan25[[#This Row],[RosterIndex]])&"" -> QB | H5: =INDEX(CompositeRoster[source],RosterPlan25[[#This Row],[RosterIndex]]) -> Roster | I5: =_xlfn.IFNA(INDEX(Draft2025[PRICE],RosterPlan25[[#This Row],[DraftIndex]]),0) -> 3 | J5: =IF(RosterPlan25[[#This Row],[SOURCE]]="Rookie","Rookie",_xlfn.IFNA(INDEX(Draft2025[Current Contract],RosterPlan25[[#This Row],[DraftIndex]]),"Undrafted")) -> Rookie | K5: {=IF(OR(ISBLANK(RosterPlan25[[#This Row],[player_id]]),NOT(ISNA(MATCH(RosterPlan25[[#This Row],[player_id]],INDIRECT("Rookies" & SEASON &"[player_id]"),0)))), SEASON, _xlfn.IFNA(INDEX(Draft2025[Contract Year],RosterPlan25[[#This Row],[DraftIndex]]),IF(IN_SEASON,SEASON,SEASON-1)))} -> 2019 | L5: =IF(_xlfn.IFNA(INDEX(Draft2025[KEEPER],RosterPlan25[[#This Row],[DraftIndex]]),"")="K","Yes","") -> Yes | M5: {=IF(RosterPlan25[[#This Row],[Contract]]="Rookie", "", IF(_xlfn.IFNA(INDEX(Draft2025[Contract Year],RosterPlan25[[#This Row],[DraftIndex]]),IF(IN_SEASON,SEASON,SEASON-1))+3<SEASON, SEASON, _xlfn.IFNA(INDEX(Draft2025[Contract Year],RosterPlan25[[#This Row],[DraftIndex]]),IF(IN_SEASON,SEASON,SEASON-1))+3))} | N5: =ROUNDDOWN(RosterPlan25[[#This Row],[Optimal $]]*IF(RosterPlan25[[#This Row],[Contract]]="Rookie",0.3,0.15),0) -> 0 | O5: =IF(RosterPlan25[[#This Row],[SOURCE]]="Rookie", INDEX(INDIRECT("Rookies" & SEASON & "[salary]"),MATCH(RosterPlan25[[#This Row],[PLAYER]],INDIRECT("Rookies"& SEASON & "[full_name]"),0)), MAX(RosterPlan25[[#This Row],[$ PREV]] + IF(RAISES_ENABLED,RosterPlan25[[#This Row],[$↑ VAR]],0),1)) -> 3 | P5: =IF(VARG="MANUAL",RosterPlan25[[#This Row],[ManualVARG]],IF(VARG="GOOD",RosterPlan25[[#This Row],[GoodVARG]],"ERR")) -> -2.9186835 | Q5: =_xlfn.IFNA(IF(RosterPlan25[[#This Row],[POS]]="K",0,INDEX(GoodSheets[MG VARG],MATCH(TEXT(RosterPlan25[[#This Row],[player_id]],"0"),GoodSheets[sleeper_id],0))), IF(RosterPlan25[[#This Row],[POS]]="QB",-12,IF(RosterPlan25[[#This Row],[POS]]="RB",-8,IF(RosterPlan25[[#This Row],[POS]]="WR",-8,-5)))) -> -2.9186835 | R5: =_xlfn.IFNA(INDEX(ALL_Athletic[VARG], MATCH(RosterPlan25[[#This Row],[player_id]],ALL_Athletic[SleeperID],0)), IF(RosterPlan25[[#This Row],[POS]]="QB",-12,IF(RosterPlan25[[#This Row],[POS]]="RB",-8,IF(RosterPlan25[[#This Row],[POS]]="WR",-8,-5)))) -> 0.58442541 | S5: K | T5: =_xlfn.IFNA(INDEX(Draft2025[Net Keeper Count],RosterPlan25[[#This Row],[DraftIndex]]),0)+IF(RosterPlan25[[#This Row],[KEEPER / RFA]]="K",1,0) -> 7 | U5: =IF(RosterPlan25[[#This Row],[KEEPER / RFA]]="RFA",RosterPlan25[[#This Row],[Pure Inflated $]],"") | V5: =IF(RosterPlan25[[#This Row],[VAR/G]]>0, ROUND(IF(VARG="GOOD",$AG$29,IF(VARG="ATHLETIC",$AH$29,99999999999))*RosterPlan25[[#This Row],[VAR/G]],0), 0) + 1 -> 1 | W5: =RosterPlan25[[#This Row],[Optimal $]]-RosterPlan25[[#This Row],[$ CURR]] -> -2 | X5: =IF(OR(RosterPlan25[[#This Row],[SOURCE]]="Rookie",RosterPlan25[[#This Row],[POS]]="K"),0,RosterPlan25[[#This Row],[VAR/G]]+3.3) -> 0.38131648 | Y5: =IF(RosterPlan25[[#This Row],[VAW/G]]>0,ROUND(RosterPlan25[[#This Row],[VAW/G]]*$AG$56,0)+1,1) -> 7 | Z5: =RosterPlan25[[#This Row],[VAWG Market $]]-_xlfn.IFNA(RosterPlan25[[#This Row],[$ CURR]],1) -> 4 | AA5: =IF(RosterPlan25[[#This Row],[VAR/G]]>0,1+ROUND(RosterPlan25[[#This Row],[VAR/G]]*IF(RosterPlan25[[#This Row],[KEEPER / RFA]]="K",($AG$34+RosterPlan25[[#This Row],[$ CURR]]-1)/($AG$23+RosterPlan25[[#This Row],[VAR/G]]),$AG$35),0),1) -> 1 | AB5: =RosterPlan25[[#This Row],[Pure Inflated $]]-RosterPlan25[[#This Row],[$ CURR]] -> -2 | AC5: =INDEX(players[age],MATCH(RosterPlan25[[#This Row],[player_id]],players[sleeper_id],0)) -> 29 | AE5: =300-AG5+AI5+$AE$15-24-AL5 -> 25 | AF5: hellj85 | AG5: =SUMIFS(RosterPlan25[[$ CURR]:[$ CURR]],RosterPlan25[[OWNER]:[OWNER]],"="&$AF5,RosterPlan25[[KEEPER / RFA]:[KEEPER / RFA]],"K") -> 281 | AH5: =SUMIFS(RosterPlan25[[$ CURR]:[$ CURR]],RosterPlan25[[OWNER]:[OWNER]],"="&$AF5,RosterPlan25[[KEEPER / RFA]:[KEEPER / RFA]],"K")+ SUMIFS(RosterPlan25[[RFA $]:[RFA $]],RosterPlan25[[OWNER]:[OWNER]],"="&$AF5,RosterPlan25[[KEEPER / RFA]:[KEEPER / RFA]],"RFA") -> 281 | AI5: =COUNTIFS(RosterPlan25[OWNER],"="&$AF5) -> 22 | AJ5: =COUNTIFS(RosterPlan25[OWNER],"="&$AF5,RosterPlan25[KEEPER / RFA],"K") -> 22 | AK5: =COUNTIFS(RosterPlan25[OWNER],"="&$AF5,RosterPlan25[KEEPER / RFA],"RFA") -> 0 | AM5: =AH5+24+AL5-MIN(AJ5+AK5,24) -> 283 | AN5: =SUMIFS(RosterPlan25[[VAR/G]:[VAR/G]],RosterPlan25[[OWNER]:[OWNER]],"="&$AF5,RosterPlan25[[KEEPER / RFA]:[KEEPER / RFA]],"K",RosterPlan25[[VAR/G]:[VAR/G]],">0") -> 33.552718 | AO5: =SUMIFS(RosterPlan25[[VAR/G]:[VAR/G]],RosterPlan25[[OWNER]:[OWNER]],"="&$AF5,RosterPlan25[[KEEPER / RFA]:[KEEPER / RFA]],"RFA",RosterPlan25[[VAR/G]:[VAR/G]],">0") -> 0 | AP5: =SUMIFS(RosterPlan25[[VAR/G]:[VAR/G]],RosterPlan25[[OWNER]:[OWNER]],"="&$AF5,RosterPlan25[[KEEPER / RFA]:[KEEPER / RFA]],"<>K",RosterPlan25[[VAR/G]:[VAR/G]],">0") -> 0 | AQ5: =(300-AM5)/IF(VARG="ATHLETIC",$AH$35,IF(VARG="GOOD",$AG$35,0)) -> 1.0345888 | AR5: =AN5+AQ5+AO5 -> 34.587307 | AS5: 23.052842 | AT5: =AR5-AS5 -> 11.534465 | AU5: =AR5/$AR$12 -> 0.14776372
A6: 8698 | B6: BobbyBaby | C6: Jake Tonges | D6: =_xlfn.IFNA(MATCH(RosterPlan25[[#This Row],[player_id]],CompositeRoster[sleeper_id],0), MATCH(RosterPlan25[[#This Row],[PLAYER]],CompositeRoster[full_name],0)) -> 5 | E6: =MATCH(RosterPlan25[[#This Row],[player_id]],Draft2025[sleeper_id],0) -> #N/A | F6: =INDEX(CompositeRoster[team],RosterPlan25[[#This Row],[RosterIndex]])&"" -> SF | G6: =INDEX(CompositeRoster[position],RosterPlan25[[#This Row],[RosterIndex]])&"" -> TE | H6: =INDEX(CompositeRoster[source],RosterPlan25[[#This Row],[RosterIndex]]) -> Roster | I6: =_xlfn.IFNA(INDEX(Draft2025[PRICE],RosterPlan25[[#This Row],[DraftIndex]]),0) -> 0 | J6: =IF(RosterPlan25[[#This Row],[SOURCE]]="Rookie","Rookie",_xlfn.IFNA(INDEX(Draft2025[Current Contract],RosterPlan25[[#This Row],[DraftIndex]]),"Undrafted")) -> Undrafted | K6: {=IF(OR(ISBLANK(RosterPlan25[[#This Row],[player_id]]),NOT(ISNA(MATCH(RosterPlan25[[#This Row],[player_id]],INDIRECT("Rookies" & SEASON &"[player_id]"),0)))), SEASON, _xlfn.IFNA(INDEX(Draft2025[Contract Year],RosterPlan25[[#This Row],[DraftIndex]]),IF(IN_SEASON,SEASON,SEASON-1)))} -> 2025 | L6: =IF(_xlfn.IFNA(INDEX(Draft2025[KEEPER],RosterPlan25[[#This Row],[DraftIndex]]),"")="K","Yes","") | M6: {=IF(RosterPlan25[[#This Row],[Contract]]="Rookie", "", IF(_xlfn.IFNA(INDEX(Draft2025[Contract Year],RosterPlan25[[#This Row],[DraftIndex]]),IF(IN_SEASON,SEASON,SEASON-1))+3<SEASON, SEASON, _xlfn.IFNA(INDEX(Draft2025[Contract Year],RosterPlan25[[#This Row],[DraftIndex]]),IF(IN_SEASON,SEASON,SEASON-1))+3))} -> 2028 | N6: =ROUNDDOWN(RosterPlan25[[#This Row],[Optimal $]]*IF(RosterPlan25[[#This Row],[Contract]]="Rookie",0.3,0.15),0) -> 0 | O6: =IF(RosterPlan25[[#This Row],[SOURCE]]="Rookie", INDEX(INDIRECT("Rookies" & SEASON & "[salary]"),MATCH(RosterPlan25[[#This Row],[PLAYER]],INDIRECT("Rookies"& SEASON & "[full_name]"),0)), MAX(RosterPlan25[[#This Row],[$ PREV]] + IF(RAISES_ENABLED,RosterPlan25[[#This Row],[$↑ VAR]],0),1)) -> 1 | P6: =IF(VARG="MANUAL",RosterPlan25[[#This Row],[ManualVARG]],IF(VARG="GOOD",RosterPlan25[[#This Row],[GoodVARG]],"ERR")) -> -4.5165313 | Q6: =_xlfn.IFNA(IF(RosterPlan25[[#This Row],[POS]]="K",0,INDEX(GoodSheets[MG VARG],MATCH(TEXT(RosterPlan25[[#This Row],[player_id]],"0"),GoodSheets[sleeper_id],0))), IF(RosterPlan25[[#This Row],[POS]]="QB",-12,IF(RosterPlan25[[#This Row],[POS]]="RB",-8,IF(RosterPlan25[[#This Row],[POS]]="WR",-8,-5)))) -> -4.5165313 | R6: =_xlfn.IFNA(INDEX(ALL_Athletic[VARG], MATCH(RosterPlan25[[#This Row],[player_id]],ALL_Athletic[SleeperID],0)), IF(RosterPlan25[[#This Row],[POS]]="QB",-12,IF(RosterPlan25[[#This Row],[POS]]="RB",-8,IF(RosterPlan25[[#This Row],[POS]]="WR",-8,-5)))) -> -5 | S6: K | T6: =_xlfn.IFNA(INDEX(Draft2025[Net Keeper Count],RosterPlan25[[#This Row],[DraftIndex]]),0)+IF(RosterPlan25[[#This Row],[KEEPER / RFA]]="K",1,0) -> 1 | U6: =IF(RosterPlan25[[#This Row],[KEEPER / RFA]]="RFA",RosterPlan25[[#This Row],[Pure Inflated $]],"") | V6: =IF(RosterPlan25[[#This Row],[VAR/G]]>0, ROUND(IF(VARG="GOOD",$AG$29,IF(VARG="ATHLETIC",$AH$29,99999999999))*RosterPlan25[[#This Row],[VAR/G]],0), 0) + 1 -> 1 | W6: =RosterPlan25[[#This Row],[Optimal $]]-RosterPlan25[[#This Row],[$ CURR]] -> 0 | X6: =IF(OR(RosterPlan25[[#This Row],[SOURCE]]="Rookie",RosterPlan25[[#This Row],[POS]]="K"),0,RosterPlan25[[#This Row],[VAR/G]]+3.3) -> -1.2165313 | Y6: =IF(RosterPlan25[[#This Row],[VAW/G]]>0,ROUND(RosterPlan25[[#This Row],[VAW/G]]*$AG$56,0)+1,1) -> 1 | Z6: =RosterPlan25[[#This Row],[VAWG Market $]]-_xlfn.IFNA(RosterPlan25[[#This Row],[$ CURR]],1) -> 0 | AA6: =IF(RosterPlan25[[#This Row],[VAR/G]]>0,1+ROUND(RosterPlan25[[#This Row],[VAR/G]]*IF(RosterPlan25[[#This Row],[KEEPER / RFA]]="K",($AG$34+RosterPlan25[[#This Row],[$ CURR]]-1)/($AG$23+RosterPlan25[[#This Row],[VAR/G]]),$AG$35),0),1) -> 1 | AB6: =RosterPlan25[[#This Row],[Pure Inflated $]]-RosterPlan25[[#This Row],[$ CURR]] -> 0 | AC6: =INDEX(players[age],MATCH(RosterPlan25[[#This Row],[player_id]],players[sleeper_id],0)) -> 27 | AE6: =300-AG6+AI6+$AE$15-24-AL6 -> 149 | AF6: demboys26 | AG6: =SUMIFS(RosterPlan25[[$ CURR]:[$ CURR]],RosterPlan25[[OWNER]:[OWNER]],"="&$AF6,RosterPlan25[[KEEPER / RFA]:[KEEPER / RFA]],"K") -> 153 | AH6: =SUMIFS(RosterPlan25[[$ CURR]:[$ CURR]],RosterPlan25[[OWNER]:[OWNER]],"="&$AF6,RosterPlan25[[KEEPER / RFA]:[KEEPER / RFA]],"K")+ SUMIFS(RosterPlan25[[RFA $]:[RFA $]],RosterPlan25[[OWNER]:[OWNER]],"="&$AF6,RosterPlan25[[KEEPER / RFA]:[KEEPER / RFA]],"RFA") -> 153 | AI6: =COUNTIFS(RosterPlan25[OWNER],"="&$AF6) -> 18 | AJ6: =COUNTIFS(RosterPlan25[OWNER],"="&$AF6,RosterPlan25[KEEPER / RFA],"K") -> 18 | AK6: =COUNTIFS(RosterPlan25[OWNER],"="&$AF6,RosterPlan25[KEEPER / RFA],"RFA") -> 0 | AM6: =AH6+24+AL6-MIN(AJ6+AK6,24) -> 159 | AN6: =SUMIFS(RosterPlan25[[VAR/G]:[VAR/G]],RosterPlan25[[OWNER]:[OWNER]],"="&$AF6,RosterPlan25[[KEEPER / RFA]:[KEEPER / RFA]],"K",RosterPlan25[[VAR/G]:[VAR/G]],">0") -> 8.6664426 | AO6: =SUMIFS(RosterPlan25[[VAR/G]:[VAR/G]],RosterPlan25[[OWNER]:[OWNER]],"="&$AF6,RosterPlan25[[KEEPER / RFA]:[KEEPER / RFA]],"RFA",RosterPlan25[[VAR/G]:[VAR/G]],">0") -> 0 | AP6: =SUMIFS(RosterPlan25[[VAR/G]:[VAR/G]],RosterPlan25[[OWNER]:[OWNER]],"="&$AF6,RosterPlan25[[KEEPER / RFA]:[KEEPER / RFA]],"<>K",RosterPlan25[[VAR/G]:[VAR/G]],">0") -> 0 | AQ6: =(300-AM6)/IF(VARG="ATHLETIC",$AH$35,IF(VARG="GOOD",$AG$35,0)) -> 8.5810016 | AR6: =AN6+AQ6+AO6 -> 17.247444 | AS6: 27.344519 | AT6: =AR6-AS6 -> -10.097075 | AU6: =AR6/$AR$12 -> 0.073684445
A7: 5947 | B7: BobbyBaby | C7: Jakobi Meyers | D7: =_xlfn.IFNA(MATCH(RosterPlan25[[#This Row],[player_id]],CompositeRoster[sleeper_id],0), MATCH(RosterPlan25[[#This Row],[PLAYER]],CompositeRoster[full_name],0)) -> 6 | E7: =MATCH(RosterPlan25[[#This Row],[player_id]],Draft2025[sleeper_id],0) -> 174 | F7: =INDEX(CompositeRoster[team],RosterPlan25[[#This Row],[RosterIndex]])&"" -> JAX | G7: =INDEX(CompositeRoster[position],RosterPlan25[[#This Row],[RosterIndex]])&"" -> WR | H7: =INDEX(CompositeRoster[source],RosterPlan25[[#This Row],[RosterIndex]]) -> Roster | I7: =_xlfn.IFNA(INDEX(Draft2025[PRICE],RosterPlan25[[#This Row],[DraftIndex]]),0) -> 8 | J7: =IF(RosterPlan25[[#This Row],[SOURCE]]="Rookie","Rookie",_xlfn.IFNA(INDEX(Draft2025[Current Contract],RosterPlan25[[#This Row],[DraftIndex]]),"Undrafted")) -> Auction | K7: {=IF(OR(ISBLANK(RosterPlan25[[#This Row],[player_id]]),NOT(ISNA(MATCH(RosterPlan25[[#This Row],[player_id]],INDIRECT("Rookies" & SEASON &"[player_id]"),0)))), SEASON, _xlfn.IFNA(INDEX(Draft2025[Contract Year],RosterPlan25[[#This Row],[DraftIndex]]),IF(IN_SEASON,SEASON,SEASON-1)))} -> 2024 | L7: =IF(_xlfn.IFNA(INDEX(Draft2025[KEEPER],RosterPlan25[[#This Row],[DraftIndex]]),"")="K","Yes","") -> Yes | M7: {=IF(RosterPlan25[[#This Row],[Contract]]="Rookie", "", IF(_xlfn.IFNA(INDEX(Draft2025[Contract Year],RosterPlan25[[#This Row],[DraftIndex]]),IF(IN_SEASON,SEASON,SEASON-1))+3<SEASON, SEASON, _xlfn.IFNA(INDEX(Draft2025[Contract Year],RosterPlan25[[#This Row],[DraftIndex]]),IF(IN_SEASON,SEASON,SEASON-1))+3))} -> 2027 | N7: =ROUNDDOWN(RosterPlan25[[#This Row],[Optimal $]]*IF(RosterPlan25[[#This Row],[Contract]]="Rookie",0.3,0.15),0) -> 0 | O7: =IF(RosterPlan25[[#This Row],[SOURCE]]="Rookie", INDEX(INDIRECT("Rookies" & SEASON & "[salary]"),MATCH(RosterPlan25[[#This Row],[PLAYER]],INDIRECT("Rookies"& SEASON & "[full_name]"),0)), MAX(RosterPlan25[[#This Row],[$ PREV]] + IF(RAISES_ENABLED,RosterPlan25[[#This Row],[$↑ VAR]],0),1)) -> 8 | P7: =IF(VARG="MANUAL",RosterPlan25[[#This Row],[ManualVARG]],IF(VARG="GOOD",RosterPlan25[[#This Row],[GoodVARG]],"ERR")) -> -0.48171702 | Q7: =_xlfn.IFNA(IF(RosterPlan25[[#This Row],[POS]]="K",0,INDEX(GoodSheets[MG VARG],MATCH(TEXT(RosterPlan25[[#This Row],[player_id]],"0"),GoodSheets[sleeper_id],0))), IF(RosterPlan25[[#This Row],[POS]]="QB",-12,IF(RosterPlan25[[#This Row],[POS]]="RB",-8,IF(RosterPlan25[[#This Row],[POS]]="WR",-8,-5)))) -> -0.48171702 | R7: =_xlfn.IFNA(INDEX(ALL_Athletic[VARG], MATCH(RosterPlan25[[#This Row],[player_id]],ALL_Athletic[SleeperID],0)), IF(RosterPlan25[[#This Row],[POS]]="QB",-12,IF(RosterPlan25[[#This Row],[POS]]="RB",-8,IF(RosterPlan25[[#This Row],[POS]]="WR",-8,-5)))) -> -0.09253197 | S7: K | T7: =_xlfn.IFNA(INDEX(Draft2025[Net Keeper Count],RosterPlan25[[#This Row],[DraftIndex]]),0)+IF(RosterPlan25[[#This Row],[KEEPER / RFA]]="K",1,0) -> 2 | U7: =IF(RosterPlan25[[#This Row],[KEEPER / RFA]]="RFA",RosterPlan25[[#This Row],[Pure Inflated $]],"") | V7: =IF(RosterPlan25[[#This Row],[VAR/G]]>0, ROUND(IF(VARG="GOOD",$AG$29,IF(VARG="ATHLETIC",$AH$29,99999999999))*RosterPlan25[[#This Row],[VAR/G]],0), 0) + 1 -> 1 | W7: =RosterPlan25[[#This Row],[Optimal $]]-RosterPlan25[[#This Row],[$ CURR]] -> -7 | X7: =IF(OR(RosterPlan25[[#This Row],[SOURCE]]="Rookie",RosterPlan25[[#This Row],[POS]]="K"),0,RosterPlan25[[#This Row],[VAR/G]]+3.3) -> 2.818283 | Y7: =IF(RosterPlan25[[#This Row],[VAW/G]]>0,ROUND(RosterPlan25[[#This Row],[VAW/G]]*$AG$56,0)+1,1) -> 47 | Z7: =RosterPlan25[[#This Row],[VAWG Market $]]-_xlfn.IFNA(RosterPlan25[[#This Row],[$ CURR]],1) -> 39 | AA7: =IF(RosterPlan25[[#This Row],[VAR/G]]>0,1+ROUND(RosterPlan25[[#This Row],[VAR/G]]*IF(RosterPlan25[[#This Row],[KEEPER / RFA]]="K",($AG$34+RosterPlan25[[#This Row],[$ CURR]]-1)/($AG$23+RosterPlan25[[#This Row],[VAR/G]]),$AG$35),0),1) -> 1 | AB7: =RosterPlan25[[#This Row],[Pure Inflated $]]-RosterPlan25[[#This Row],[$ CURR]] -> -7 | AC7: =INDEX(players[age],MATCH(RosterPlan25[[#This Row],[player_id]],players[sleeper_id],0)) -> 29 | AE7: =300-AG7+AI7+$AE$15-24-AL7 -> 149 | AF7: BobbyBaby | AG7: =SUMIFS(RosterPlan25[[$ CURR]:[$ CURR]],RosterPlan25[[OWNER]:[OWNER]],"="&$AF7,RosterPlan25[[KEEPER / RFA]:[KEEPER / RFA]],"K") -> 156 | AH7: =SUMIFS(RosterPlan25[[$ CURR]:[$ CURR]],RosterPlan25[[OWNER]:[OWNER]],"="&$AF7,RosterPlan25[[KEEPER / RFA]:[KEEPER / RFA]],"K")+ SUMIFS(RosterPlan25[[RFA $]:[RFA $]],RosterPlan25[[OWNER]:[OWNER]],"="&$AF7,RosterPlan25[[KEEPER / RFA]:[KEEPER / RFA]],"RFA") -> 156 | AI7: =COUNTIFS(RosterPlan25[OWNER],"="&$AF7) -> 21 | AJ7: =COUNTIFS(RosterPlan25[OWNER],"="&$AF7,RosterPlan25[KEEPER / RFA],"K") -> 21 | AK7: =COUNTIFS(RosterPlan25[OWNER],"="&$AF7,RosterPlan25[KEEPER / RFA],"RFA") -> 0 | AM7: =AH7+24+AL7-MIN(AJ7+AK7,24) -> 159 | AN7: =SUMIFS(RosterPlan25[[VAR/G]:[VAR/G]],RosterPlan25[[OWNER]:[OWNER]],"="&$AF7,RosterPlan25[[KEEPER / RFA]:[KEEPER / RFA]],"K",RosterPlan25[[VAR/G]:[VAR/G]],">0") -> 8.8920078 | AO7: =SUMIFS(RosterPlan25[[VAR/G]:[VAR/G]],RosterPlan25[[OWNER]:[OWNER]],"="&$AF7,RosterPlan25[[KEEPER / RFA]:[KEEPER / RFA]],"RFA",RosterPlan25[[VAR/G]:[VAR/G]],">0") -> 0 | AP7: =SUMIFS(RosterPlan25[[VAR/G]:[VAR/G]],RosterPlan25[[OWNER]:[OWNER]],"="&$AF7,RosterPlan25[[KEEPER / RFA]:[KEEPER / RFA]],"<>K",RosterPlan25[[VAR/G]:[VAR/G]],">0") -> 0 | AQ7: =(300-AM7)/IF(VARG="ATHLETIC",$AH$35,IF(VARG="GOOD",$AG$35,0)) -> 8.5810016 | AR7: =AN7+AQ7+AO7 -> 17.473009 | AS7: 22.682308 | AT7: =AR7-AS7 -> -5.2092983 | AU7: =AR7/$AR$12 -> 0.074648104
